
‚ùå CRITICAL ERROR: Manager isn't available; 'auth.User' has been swapped for 'chart.User'
Error Type: AttributeError
Traceback:
Traceback (most recent call last):
  File "C:\Users\trueb\outer-skies\test_phase2_monitoring.py", line 486, in main
    tester = Phase2MonitoringTests()
             ^^^^^^^^^^^^^^^^^^^^^^^
  File "C:\Users\trueb\outer-skies\test_phase2_monitoring.py", line 61, in __init__
    self.test_user, created = User.objects.get_or_create(
                              ^^^^^^^^^^^^
  File "C:\Users\trueb\outer-skies\venv311\Lib\site-packages\django\db\models\manager.py", line 196, in __get__
    raise AttributeError(
AttributeError: Manager isn't available; 'auth.User' has been swapped for 'chart.User'

